<?xml version="1.0"?>
<robot name="exam_robot">

  <!-- ================= BASE LINK ================= -->
  <link name="base_link">
    <visual>
      <geometry>
        <box size="0.4 0.3 0.1"/>
      </geometry>
      <material name="blue">
        <color rgba="0 0 0.8 1"/>
      </material>
    </visual>
    <collision>
      <geometry>
        <box size="0.4 0.3 0.1"/>
      </geometry>
    </collision>
    <inertial>
      <mass value="5.0"/>
      <inertia ixx="0.1" ixy="0.0" ixz="0.0" iyy="0.1" iyz="0.0" izz="0.1"/>
    </inertial>
  </link>

  <!-- ================= LEFT WHEEL ================= -->
  <link name="wheel_left_link">
    <visual>
      <geometry>
        <cylinder length="0.05" radius="0.1"/>
      </geometry>
      <material name="black">
        <color rgba="0.1 0.1 0.1 1"/>
      </material>
    </visual>
    <collision>
      <geometry>
        <cylinder length="0.05" radius="0.1"/>
      </geometry>
    </collision>
    <inertial>
      <mass value="0.5"/>
      <inertia ixx="0.01" ixy="0.0" ixz="0.0" iyy="0.01" iyz="0.0" izz="0.01"/>
    </inertial>
  </link>

  <joint name="base_to_left_wheel" type="continuous">
    <parent link="base_link"/>
    <child link="wheel_left_link"/>
    <origin xyz="0 0.175 0" rpy="1.5708 0 0"/>
    <axis xyz="0 0 1"/>
  </joint>

  <!-- ================= RIGHT WHEEL ================= -->
  <link name="wheel_right_link">
    <visual>
      <geometry>
        <cylinder length="0.05" radius="0.1"/>
      </geometry>
      <material name="black">
        <color rgba="0.1 0.1 0.1 1"/>
      </material>
    </visual>
    <collision>
      <geometry>
        <cylinder length="0.05" radius="0.1"/>
      </geometry>
    </collision>
    <inertial>
      <mass value="0.5"/>
      <inertia ixx="0.01" ixy="0.0" ixz="0.0" iyy="0.01" iyz="0.0" izz="0.01"/>
    </inertial>
  </link>

  <joint name="base_to_right_wheel" type="continuous">
    <parent link="base_link"/>
    <child link="wheel_right_link"/>
    <origin xyz="0 -0.175 0" rpy="1.5708 0 0"/>
    <axis xyz="0 0 1"/>
  </joint>

  <!-- ================= SENSOR ================= -->
  <link name="sensor_link">
    <visual>
      <geometry>
        <box size="0.05 0.05 0.05"/>
      </geometry>
      <material name="red">
        <color rgba="1 0 0 1"/>
      </material>
    </visual>
  </link>

  <joint name="base_to_sensor" type="fixed">
    <parent link="base_link"/>
    <child link="sensor_link"/>
    <origin xyz="0.2 0 0.08" rpy="0 0 0"/>
  </joint>

</robot>
